import {
  ConflictException,
  InternalServerErrorException,
} from '@nestjs/common';
import { EntityRepository, Repository } from 'typeorm';
import * as bcrypt from 'bcrypt';
import { AuthCredentialsDto } from './DTOs/auth-credentials.dto';
import { User } from './user.entity';

@EntityRepository(User)
export class UserRepository extends Repository<User> {
  async signUp(authCredentialsDto: AuthCredentialsDto): Promise<void> {
    const { username, password } = authCredentialsDto;

    const salt = await bcrypt.genSalt();
    const user = new User();
    user.username = username;
    user.salt = salt;
    user.password = await this.hashPassword(password, salt);

    try {
      await user.save();
    } catch (error) {
      if (error.code === '23505') {
        throw new ConflictException('username already exsists');
      } else {
        throw new InternalServerErrorException();
      }
    }
  }

  async validateUser(authCredentialsDto: AuthCredentialsDto): Promise<string> {
    const { username, password } = authCredentialsDto;

    const user = await this.findOne({ username });

    if (user && (await user.validatePassword(password))) {
      return user.username;
    } else {
      return null;
    }
  }

  private async hashPassword(password: string, salt: string): Promise<string> {
    return bcrypt.hash(password, salt);
  }
}
